49695:C 11 Oct 2025 18:48:55.207 * oO0OoO0OoO0Oo Redis is starting oO0OoO0OoO0Oo
49695:C 11 Oct 2025 18:48:55.207 * Redis version=7.2.6, bits=64, commit=00000000, modified=0, pid=49695, just started
49695:C 11 Oct 2025 18:48:55.207 # Warning: no config file specified, using the default config. In order to specify a config file use redis-server /path/to/redis.conf
49695:M 11 Oct 2025 18:48:55.208 * monotonic clock: POSIX clock_gettime
49695:M 11 Oct 2025 18:48:55.210 * Running mode=standalone, port=6379.
49695:M 11 Oct 2025 18:48:55.210 # Warning: Could not create server TCP listening socket *:6379: bind: Address already in use
49695:M 11 Oct 2025 18:48:55.211 # Failed listening on port 6379 (tcp), aborting.
Usage: celery [OPTIONS] COMMAND [ARGS]...
Try 'celery --help' for help.

Usage: celery [OPTIONS] COMMAND [ARGS]...
Try 'celery --help' for help.

Error: Invalid value for '-A' / '--app': 
Unable to load celery application.
While trying to load the module main.celery the following error occurred:
Traceback (most recent call last):
  File "/home/user/documentprocessor/.venv/lib/python3.11/site-packages/celery/bin/celery.py", line 58, in convert
    return find_app(value)
           ^^^^^^^^^^^^^^^
  File "/home/user/documentprocessor/.venv/lib/python3.11/site-packages/celery/app/utils.py", line 383, in find_app
    sym = symbol_by_name(app, imp=imp)
          ^^^^^^^^^^^^^^^^^^^^^^^^^^^^
  File "/home/user/documentprocessor/.venv/lib/python3.11/site-packages/kombu/utils/imports.py", line 59, in symbol_by_name
    module = imp(module_name, package=package, **kwargs)
             ^^^^^^^^^^^^^^^^^^^^^^^^^^^^^^^^^^^^^^^^^^^
  File "/home/user/documentprocessor/.venv/lib/python3.11/site-packages/celery/utils/imports.py", line 109, in import_from_cwd
    return imp(module, package=package)
           ^^^^^^^^^^^^^^^^^^^^^^^^^^^^
  File "/usr/lib/python3.11/importlib/__init__.py", line 126, in import_module
    return _bootstrap._gcd_import(name[level:], package, level)
           ^^^^^^^^^^^^^^^^^^^^^^^^^^^^^^^^^^^^^^^^^^^^^^^^^^^^
  File "<frozen importlib._bootstrap>", line 1204, in _gcd_import
  File "<frozen importlib._bootstrap>", line 1176, in _find_and_load
  File "<frozen importlib._bootstrap>", line 1147, in _find_and_load_unlocked
  File "<frozen importlib._bootstrap>", line 690, in _load_unlocked
  File "<frozen importlib._bootstrap_external>", line 940, in exec_module
  File "<frozen importlib._bootstrap>", line 241, in _call_with_frames_removed
  File "/home/user/documentprocessor/main.py", line 13, in <module>
    from app import create_app
ImportError: cannot import name 'create_app' from 'app' (/home/user/documentprocessor/app.py)

Error: Invalid value for '-A' / '--app': 
Unable to load celery application.
While trying to load the module main.celery the following error occurred:
Traceback (most recent call last):
  File "/home/user/documentprocessor/.venv/lib/python3.11/site-packages/celery/bin/celery.py", line 58, in convert
    return find_app(value)
           ^^^^^^^^^^^^^^^
  File "/home/user/documentprocessor/.venv/lib/python3.11/site-packages/celery/app/utils.py", line 383, in find_app
    sym = symbol_by_name(app, imp=imp)
          ^^^^^^^^^^^^^^^^^^^^^^^^^^^^
  File "/home/user/documentprocessor/.venv/lib/python3.11/site-packages/kombu/utils/imports.py", line 59, in symbol_by_name
    module = imp(module_name, package=package, **kwargs)
             ^^^^^^^^^^^^^^^^^^^^^^^^^^^^^^^^^^^^^^^^^^^
  File "/home/user/documentprocessor/.venv/lib/python3.11/site-packages/celery/utils/imports.py", line 109, in import_from_cwd
    return imp(module, package=package)
           ^^^^^^^^^^^^^^^^^^^^^^^^^^^^
  File "/usr/lib/python3.11/importlib/__init__.py", line 126, in import_module
    return _bootstrap._gcd_import(name[level:], package, level)
           ^^^^^^^^^^^^^^^^^^^^^^^^^^^^^^^^^^^^^^^^^^^^^^^^^^^^
  File "<frozen importlib._bootstrap>", line 1204, in _gcd_import
  File "<frozen importlib._bootstrap>", line 1176, in _find_and_load
  File "<frozen importlib._bootstrap>", line 1147, in _find_and_load_unlocked
  File "<frozen importlib._bootstrap>", line 690, in _load_unlocked
  File "<frozen importlib._bootstrap_external>", line 940, in exec_module
  File "<frozen importlib._bootstrap>", line 241, in _call_with_frames_removed
  File "/home/user/documentprocessor/main.py", line 13, in <module>
    from app import create_app
ImportError: cannot import name 'create_app' from 'app' (/home/user/documentprocessor/app.py)

Usage: flask run [OPTIONS]
Try 'flask run --help' for help.

Error: While importing 'main', an ImportError was raised:

Traceback (most recent call last):
  File "/home/user/documentprocessor/.venv/lib/python3.11/site-packages/flask/cli.py", line 245, in locate_app
    __import__(module_name)
  File "/home/user/documentprocessor/main.py", line 13, in <module>
    from app import create_app
ImportError: cannot import name 'create_app' from 'app' (/home/user/documentprocessor/app.py)

